#VRML_SIM R2023a utf8

EXTERNPROTO "https://raw.githubusercontent.com/cyberbotics/webots/R2023a/projects/objects/backgrounds/protos/TexturedBackground.proto"
EXTERNPROTO "https://raw.githubusercontent.com/cyberbotics/webots/R2023a/projects/objects/backgrounds/protos/TexturedBackgroundLight.proto"
EXTERNPROTO "https://raw.githubusercontent.com/cyberbotics/webots/R2023a/projects/objects/floors/protos/RectangleArena.proto"
EXTERNPROTO "https://raw.githubusercontent.com/cyberbotics/webots/R2023a/projects/appearances/protos/Asphalt.proto"
EXTERNPROTO "https://raw.githubusercontent.com/cyberbotics/webots/R2023a/projects/objects/balls/protos/RobocupSoccerBall.proto"
EXTERNPROTO "https://raw.githubusercontent.com/cyberbotics/webots/R2023a/projects/objects/apartment_structure/protos/Wall.proto"

WorldInfo {
  info [
    "Example use of a Bumper TouchSensor device."
  ]
  title "Bumper"
}
Viewpoint {
  orientation -0.47855411162906963 0.47915340675048373 0.7357975095379962 1.8717047364261712
  position -0.3379220117101161 -1.5368097718211602 3.3908639069777884
  follow "mybot"
  followType "None"
}
TexturedBackground {
}
TexturedBackgroundLight {
}
RectangleArena {
  floorSize 2 2
  floorAppearance Asphalt {
  }
}
Robot {
  translation 0.0020909000042405534 -0.4991773296155949 -0.0002266392482142901
  rotation -0.014419394585933833 0.014482798836134675 0.9997911429881979 1.5664012371321259
  children [
    Transform {
      translation 0 0 0.0415
      rotation 0 0 1 1.570796
      children [
        Shape {
          appearance PBRAppearance {
            baseColor 0.0820075 0.364731 0.8
            roughness 1
            metalness 0
          }
          geometry DEF BODY Cylinder {
            height 0.08
            radius 0.045
          }
        }
      ]
    }
    HingeJoint {
      jointParameters HingeJointParameters {
        position 603.9340402005552
        axis 0 1 0
        anchor 0 0 0.025
      }
      device [
        RotationalMotor {
          name "left wheel motor"
          consumptionFactor 70
        }
        PositionSensor {
          name "left wheel sensor"
        }
      ]
      endPoint Solid {
        translation 0 0.04499999999999994 0.025
        rotation -0.22945531993175705 0.22945506099467572 -0.9458861618286551 1.6264014009309287
        children [
          DEF WHEEL Transform {
            rotation 0.577656895078166 0.5771968951617173 -0.5771968951617173 -2.093935
            children [
              Shape {
                appearance PBRAppearance {
                  baseColor 1 0 0
                  roughness 1
                  metalness 0
                }
                geometry Cylinder {
                  height 0.01
                  radius 0.025
                }
              }
            ]
          }
        ]
        name "left wheel"
        boundingObject USE WHEEL
        physics DEF PHYSICS_WHEEL Physics {
          density -1
          mass 0.05
        }
        linearVelocity 0.00046049704984789294 0.09999766489202624 7.6841820113732e-07
        angularVelocity -3.999955787947375 0.018436093597281066 1.3441869426158655e-05
      }
    }
    HingeJoint {
      jointParameters HingeJointParameters {
        position 601.6326981404502
        axis 0 1 0
        anchor 0 0 0.025
      }
      device [
        RotationalMotor {
          name "right wheel motor"
          consumptionFactor 70
        }
        PositionSensor {
          name "right wheel sensor"
        }
      ]
      endPoint Solid {
        translation 0 -0.04499999999999994 0.025
        rotation 0.5478562294126758 -0.5478561772856334 -0.6322239800131739 2.0140382698851584
        children [
          USE WHEEL
        ]
        name "right wheel"
        boundingObject USE WHEEL
        physics USE PHYSICS_WHEEL
        linearVelocity 0.0004605085056471379 0.10000122538556949 -8.142386028543185e-07
        angularVelocity -3.999955874434723 0.018435417582166706 1.2566098244412024e-05
      }
    }
    Transform {
      translation 0.0385 -0.02 0.063
      rotation -0.726828171413359 -0.4856551145357015 -0.48565411453546564 -1.884582
      children [
        DEF UNUSED_EYE Group {
          children [
            Transform {
              translation 0 0 1e-05
              rotation 0 0 1 0.8
              children [
                Shape {
                  appearance PBRAppearance {
                    baseColor 0.975691 0.981481 0.0252992
                    roughness 1
                    metalness 0
                  }
                  geometry Box {
                    size 0.02 0.005 0.005
                  }
                }
              ]
            }
            Transform {
              rotation 0 0 1 -0.8
              children [
                Shape {
                  appearance PBRAppearance {
                    baseColor 0.975691 0.981481 0.0252992
                    roughness 1
                    metalness 0
                  }
                  geometry Box {
                    size 0.02 0.005 0.005
                  }
                }
              ]
            }
          ]
        }
      ]
    }
    Transform {
      translation 0.0385 0.02 0.063
      rotation -0.7268306455324123 0.4856527631523045 0.4856527631523045 -1.884578
      children [
        USE UNUSED_EYE
      ]
    }
    Shape {
      appearance PBRAppearance {
        baseColor 0.8 0.8 0.8
        baseColorMap ImageTexture {
          url [
            "https://raw.githubusercontent.com/cyberbotics/webots/R2023a/projects/samples/devices/worlds/textures/mybot.png"
          ]
        }
        roughness 0.5
        metalness 0
      }
      geometry IndexedFaceSet {
        coord Coordinate {
          point [
            0.015 0.038 -0.041
            0.015 0.023 -0.041
            0 0.023 -0.0455
            -0.015 0.023 -0.041
            -0.015 0.038 -0.041
            0 0.038 -0.0455
          ]
        }
        texCoord TextureCoordinate {
          point [
            0 0
            0.5 0
            1 0
            1 1
            0.5 1
            0 1
          ]
        }
        coordIndex [
          0, 1, 2, 5, -1, 5, 2, 3, 4, -1
        ]
        texCoordIndex [
          5, 0, 1, 4, -1, 4, 1, 2, 3, -1
        ]
        creaseAngle 0.9
      }
    }
    TouchSensor {
      translation 0.04705047224157488 0.0004888732161270879 0.01896831230934359
      rotation 1 1.8835984397117084e-10 8.134143532345771e-12 -3.1415923071282075
      children [
        Shape {
          appearance PBRAppearance {
            baseColor 0 0 0
            roughness 0.6980390000000001
            metalness 0
          }
          geometry DEF BUMPER Box {
            size 0.02 0.09 0.02
          }
        }
      ]
      name "bumper"
      boundingObject USE BUMPER
      physics Physics {
        density -1
        mass 0.01
      }
      lookupTable [
        0 0 0
        0.01 1 0
      ]
      linearVelocity 0.0004591559852062525 0.09999944887178175 6.509964251672634e-08
      angularVelocity 1.7480744903519784e-06 1.8202247806901467e-05 2.587237662906275e-05
    }
  ]
  name "mybot"
  boundingObject Transform {
    translation 0 0 0.0415
    rotation 0 0 1 1.570796
    children [
      USE BODY
    ]
  }
  physics Physics {
    density -1
    mass 0.5
  }
  controller "bumper"
  linearVelocity 0.0004607906732955902 0.09999941444239734 -2.1063581683114964e-08
  angularVelocity 1.7480744892078514e-06 1.8202247805994406e-05 2.587237662072473e-05
}
RobocupSoccerBall {
  hidden linearVelocity_0 -0.002284120769337007 -5.752252569633633e-06 -1.1538417870636678e-06
  hidden angularVelocity_0 8.214435622425534e-05 -0.03260069760949436 -8.67636971050437e-05
  translation -0.7608260306807985 0.8131750477802363 0.06987585299467317
  rotation -0.8152887866241414 0.32404664486617996 0.4798937031842646 2.1305814901235003
}
RobocupSoccerBall {
  hidden linearVelocity_0 3.6413374577369285e-12 4.684007746423922e-12 -1.3893452535187777e-12
  hidden angularVelocity_0 -2.3870909610128757e-08 3.963864081747942e-08 -1.280863562636748e-14
  translation 0.9300000463222926 0.9300000278120268 0.06987585314130915
  rotation 0.4931060765070581 0.3072381623013071 0.8139109957099309 -2.495900249785359
  name "robocup soccer ball(1)"
}
Wall {
  translation -0.17 -0.7 0
  size 0.01 0.6 0.1
}
Wall {
  translation 0.14 -0.7 0
  name "wall(7)"
  size 0.01 0.6 0.1
}
Wall {
  translation -0.29 0.2 0
  name "wall(6)"
  size 0.01 0.6 0.1
}
Wall {
  translation 0.29 0.2 0
  name "wall(10)"
  size 0.01 0.6 0.1
}
Wall {
  translation -5.14248e-07 -0.11 0
  rotation 0 0 1 1.5708
  name "wall(1)"
  size 0.01 0.6 0.1
}
Wall {
  translation -0.429999 -0.41 0
  rotation 0 0 1 1.5708
  name "wall(2)"
  size 0.01 0.5 0.1
}
Wall {
  translation -0.829999 0.0799996 0
  rotation 0 0 1 1.5708
  name "wall(13)"
  size 0.01 0.35 0.1
}
Wall {
  translation 0.800001 0.080005 0
  rotation 0 0 1 1.5708
  name "wall(14)"
  size 0.01 0.35 0.1
}
Wall {
  translation 0.390001 -0.41 0
  rotation 0 0 1 1.5708
  name "wall(8)"
  size 0.01 0.5 0.1
}
Wall {
  translation -0.48 0.51 0
  rotation 0 0 1 1.5708
  name "wall(5)"
  size 0.01 0.4 0.1
}
Wall {
  translation 0.49 0.510003 0
  rotation 0 0 1 1.5708
  name "wall(11)"
  size 0.01 0.4 0.1
}
Wall {
  translation -0.669999 -0.16 0
  rotation 0 0 -1 -5.307179586466759e-06
  name "wall(4)"
  size 0.01 0.5 0.1
}
Wall {
  translation 0.620001 -0.159993 0
  rotation 0 0 -1 -5.307179586466759e-06
  name "wall(9)"
  size 0.01 0.5 0.1
}
Wall {
  translation -0.670002 0.75 0
  rotation 0 0 1 -3.1415853071795863
  name "wall(3)"
  size 0.01 0.5 0.1
}
Wall {
  translation 0.679998 0.750008 0
  rotation 0 0 1 -3.1415853071795863
  name "wall(12)"
  size 0.01 0.5 0.1
}
